Unable to fetch any sequences. Please check the IDs or gene names and try again.

Error fetching sequence for TP53: HTTP Error 400: Bad Request Traceback (most recent call last): File "/home/runner/workspace/app.py", line 76, in fetch_sequence protein_handle = Entrez.efetch(db="protein", id=sequence_id, rettype="fasta", retmode="text") ^^^^^^^^^^^^^^^^^^^^^^^^^^^^^^^^^^^^^^^^^^^^^^^^^^^^^^^^^^^^^^^^^^^^^^^^^^^^ File "/home/runner/workspace/.pythonlibs/lib/python3.11/site-packages/Bio/Entrez/__init__.py", line 201, in efetch return _open(request) ^^^^^^^^^^^^^^ File "/home/runner/workspace/.pythonlibs/lib/python3.11/site-packages/Bio/Entrez/__init__.py", line 634, in _open handle = urlopen(request) ^^^^^^^^^^^^^^^^ File "/nix/store/f98g7xbckgqbkagdvpzc2r6lv3h1p9ki-python3-3.11.9/lib/python3.11/urllib/request.py", line 216, in urlopen return opener.open(url, data, timeout) ^^^^^^^^^^^^^^^^^^^^^^^^^^^^^^^ File "/nix/store/f98g7xbckgqbkagdvpzc2r6lv3h1p9ki-python3-3.11.9/lib/python3.11/urllib/request.py", line 525, in open response = meth(req, response) ^^^^^^^^^^^^^^^^^^^ File "/nix/store/f98g7xbckgqbkagdvpzc2r6lv3h1p9ki-python3-3.11.9/lib/python3.11/urllib/request.py", line 634, in http_response response = self.parent.error( ^^^^^^^^^^^^^^^^^^ File "/nix/store/f98g7xbckgqbkagdvpzc2r6lv3h1p9ki-python3-3.11.9/lib/python3.11/urllib/request.py", line 563, in error return self._call_chain(*args) ^^^^^^^^^^^^^^^^^^^^^^^ File "/nix/store/f98g7xbckgqbkagdvpzc2r6lv3h1p9ki-python3-3.11.9/lib/python3.11/urllib/request.py", line 496, in _call_chain result = func(*args) ^^^^^^^^^^^ File "/nix/store/f98g7xbckgqbkagdvpzc2r6lv3h1p9ki-python3-3.11.9/lib/python3.11/urllib/request.py", line 643, in http_error_default raise HTTPError(req.full_url, code, msg, hdrs, fp) urllib.error.HTTPError: HTTP Error 400: Bad Request
Error fetching sequence for NM_000546: HTTP Error 400: Bad Request Traceback (most recent call last): File "/home/runner/workspace/app.py", line 76, in fetch_sequence protein_handle = Entrez.efetch(db="protein", id=sequence_id, rettype="fasta", retmode="text") ^^^^^^^^^^^^^^^^^^^^^^^^^^^^^^^^^^^^^^^^^^^^^^^^^^^^^^^^^^^^^^^^^^^^^^^^^^^^ File "/home/runner/workspace/.pythonlibs/lib/python3.11/site-packages/Bio/Entrez/__init__.py", line 201, in efetch return _open(request) ^^^^^^^^^^^^^^ File "/home/runner/workspace/.pythonlibs/lib/python3.11/site-packages/Bio/Entrez/__init__.py", line 634, in _open handle = urlopen(request) ^^^^^^^^^^^^^^^^ File "/nix/store/f98g7xbckgqbkagdvpzc2r6lv3h1p9ki-python3-3.11.9/lib/python3.11/urllib/request.py", line 216, in urlopen return opener.open(url, data, timeout) ^^^^^^^^^^^^^^^^^^^^^^^^^^^^^^^ File "/nix/store/f98g7xbckgqbkagdvpzc2r6lv3h1p9ki-python3-3.11.9/lib/python3.11/urllib/request.py", line 525, in open response = meth(req, response) ^^^^^^^^^^^^^^^^^^^ File "/nix/store/f98g7xbckgqbkagdvpzc2r6lv3h1p9ki-python3-3.11.9/lib/python3.11/urllib/request.py", line 634, in http_response response = self.parent.error( ^^^^^^^^^^^^^^^^^^ File "/nix/store/f98g7xbckgqbkagdvpzc2r6lv3h1p9ki-python3-3.11.9/lib/python3.11/urllib/request.py", line 563, in error return self._call_chain(*args) ^^^^^^^^^^^^^^^^^^^^^^^ File "/nix/store/f98g7xbckgqbkagdvpzc2r6lv3h1p9ki-python3-3.11.9/lib/python3.11/urllib/request.py", line 496, in _call_chain result = func(*args) ^^^^^^^^^^^ File "/nix/store/f98g7xbckgqbkagdvpzc2r6lv3h1p9ki-python3-3.11.9/lib/python3.11/urllib/request.py", line 643, in http_error_default raise HTTPError(req.full_url, code, msg, hdrs, fp) urllib.error.HTTPError: HTTP Error 400: Bad Request